Traceback (most recent call last):
  File "/usr/local/pyenv/versions/3.8.9/lib/python3.8/site-packages/jupyter_cache/executors/utils.py", line 51, in single_nb_execution
    executenb(
  File "/usr/local/pyenv/versions/3.8.9/lib/python3.8/site-packages/nbclient/client.py", line 1112, in execute
    return NotebookClient(nb=nb, resources=resources, km=km, **kwargs).execute()
  File "/usr/local/pyenv/versions/3.8.9/lib/python3.8/site-packages/nbclient/util.py", line 74, in wrapped
    return just_run(coro(*args, **kwargs))
  File "/usr/local/pyenv/versions/3.8.9/lib/python3.8/site-packages/nbclient/util.py", line 53, in just_run
    return loop.run_until_complete(coro)
  File "/usr/local/pyenv/versions/3.8.9/lib/python3.8/asyncio/base_events.py", line 616, in run_until_complete
    return future.result()
  File "/usr/local/pyenv/versions/3.8.9/lib/python3.8/site-packages/nbclient/client.py", line 553, in async_execute
    await self.async_execute_cell(
  File "/usr/local/pyenv/versions/3.8.9/lib/python3.8/site-packages/nbclient/client.py", line 857, in async_execute_cell
    self._check_raise_for_error(cell, exec_reply)
  File "/usr/local/pyenv/versions/3.8.9/lib/python3.8/site-packages/nbclient/client.py", line 760, in _check_raise_for_error
    raise CellExecutionError.from_cell_and_msg(cell, exec_reply_content)
nbclient.exceptions.CellExecutionError: An error occurred while executing the following cell:
------------------
import seaborn as sns
sns.set(style="ticks")

l1, l2 = (utils.nicenumber(df.min().min(), binsize=50, lower=True), 
          utils.nicenumber(df.max().max(), binsize=50, lower=False))

def plot_unity(xdata, ydata, **kwargs):
    points = np.linspace(l1, l2, 100)
    plt.gca().plot(points, points, color='k', marker=None,
                   linestyle=':', linewidth=3.0)

g = sns.pairplot(df.dropna(how='all', axis=1).dropna(), plot_kws=dict(s=50, edgecolor="C0", linewidth=1));
g.map_offdiag(plot_unity)
for asx in g.axes:
    for ax in asx:
        ax.set_xlim((l1, l2))
        ax.set_ylim((l1, l2))

plt.savefig(os.path.join(plot_dir, 'dem_scatter.png'), dpi=150, bbox_inches='tight')
------------------

[0;31m---------------------------------------------------------------------------[0m
[0;31mModuleNotFoundError[0m                       Traceback (most recent call last)
[0;32m<ipython-input-19-66314edea33d>[0m in [0;36m<module>[0;34m[0m
[0;32m----> 1[0;31m [0;32mimport[0m [0mseaborn[0m [0;32mas[0m [0msns[0m[0;34m[0m[0;34m[0m[0m
[0m[1;32m      2[0m [0msns[0m[0;34m.[0m[0mset[0m[0;34m([0m[0mstyle[0m[0;34m=[0m[0;34m"ticks"[0m[0;34m)[0m[0;34m[0m[0;34m[0m[0m
[1;32m      3[0m [0;34m[0m[0m
[1;32m      4[0m l1, l2 = (utils.nicenumber(df.min().min(), binsize=50, lower=True), 
[1;32m      5[0m           utils.nicenumber(df.max().max(), binsize=50, lower=False))

[0;31mModuleNotFoundError[0m: No module named 'seaborn'
ModuleNotFoundError: No module named 'seaborn'

